Workbook

Sheet LIST1
DP1: Унифицированная форма № ОС-1
DP2: Утверждена распоряжением ОАО «РЖД»
DP3: от
A4: УТВЕРЖДАЮ | CN4: УТВЕРЖДАЮ
A5: Руководитель организации-сдатчика | CN5: Руководитель организации-получателя
A6: =Itemdata_1.1!B7 | AS6: =Itemdata_1.1!B8 | CN6: =+Itemdata_1.1!B2 -> Начальник | ED6: =+Itemdata_1.1!B3
A7: (должность) | AE7: (подпись) | AS7: (расшифровка подписи) | CN7: (должность) | DQ7: (подпись) | ED7: (расшифровка подписи)
H8: " | N8: " | AI8: 20 | AP8: г. | CZ8: " | DA8: =IF(Itemdata_1.1!B30>0,DAY(Itemdata_1.1!B30),"") -> 2 | DF8: " | DH8: =IF(Itemdata_1.1!B47<>"",Itemdata_1.1!B47,"") -> октября | EC8: =IF(Itemdata_1.1!B30>0,YEAR(Itemdata_1.1!B30),"") -> 2006 | EH8: г.
A9: М.П. | CN9: М.П.
EP10: Код
DU11: Форма | EE11: по ОКУД | EP11: 0306001
A12: Организация-получатель | Y12: =+Itemdata_1.1!B45 -> ОАО "Центр по перевозке грузов в контейнерах "Трансконтейнер | EE12: по ОКПО | EP12: =+Itemdata_1.1!B21 -> 94421386
BJ13: (наименование)
A14: =CONCATENATE(Itemdata_1.1!B22,IF(AND(Itemdata_1.1!B22<>"",OR(Itemdata_1.1!B23<>"",Itemdata_1.1!B24<>"")),"; ",),Itemdata_1.1!B23,IF(AND(Itemdata_1.1!B23<>"",Itemdata_1.1!B24<>""),"; ",),Itemdata_1.1!B24) -> 107174 Москва Каланчевская 6/2
A15: (адрес, телефон, факс)
A16: =+Itemdata_1.1!B25
A17: (банковские реквизиты)
A18: =+Itemdata_1.1!B20 -> ОАО «ТрансКонтейнер» | EP18: =Itemdata_1.1!C20 -> N350
A19: (наименование структурного подразделения) | EE19: по ОКПО | EP19: =+Itemdata_1.1!B14
A20: Организация-сдатчик | V20: =+Itemdata_1.1!B12
BJ21: (наименование)
A22: =CONCATENATE(Itemdata_1.1!B15,IF(AND(Itemdata_1.1!B15<>"",OR(Itemdata_1.1!B16<>"",Itemdata_1.1!B17<>"")),"; ",),Itemdata_1.1!B16,IF(AND(Itemdata_1.1!B16<>"",Itemdata_1.1!B17<>""),"; ",),Itemdata_1.1!B17)
A23: (адрес, телефон, факс)
A24: =+Itemdata_1.1!B18
A25: (банковские реквизиты)
A26: =+Itemdata_1.1!B19 | EP26: =Itemdata_1.1!C19
A27: (наименование структурного подразделения) | EC27: номер | EP27: =+Itemdata_1.1!B28
A28: Основание для составления акта | AF28: =+Itemdata_1.1!B27 | EP28: =+Itemdata_1.1!C28
AS29: (приказ, распоряжение, договор (с указанием его вида, основных обязательств)) | EC29: дата | EP29: =+Itemdata_1.1!B29
EP30: =+Itemdata_1.1!C29
CO31: Дата | DC31: принятия к бухгалтерскому учету | EP31: =IF(Itemdata_1.1!B30>0,Itemdata_1.1!B30,"") -> 02.10.2006
DC32: списания с бухгалтерского учета | EP32: =+Itemdata_1.1!B31
EN33: Счет, субсчет, код аналитического учета | EP33: =+Itemdata_1.1!B32 -> 01 04 100100
AZ34: АКТ | BL34: Номер документа | CE34: Дата составления | EN34: по ОКОФ | EP34: =+Itemdata_1.1!B33 -> 14 3020201
BL35: =+Itemdata_1.1!B42 -> 140000000062 | CE35: =IF(Itemdata_1.1!B30>0,Itemdata_1.1!B30,"") -> 02.10.2006 | DC35: Номер | DM35: амортизационной группы | EP35: =+Itemdata_1.1!B34 -> 03
AB36: о приеме-передаче объекта основных средств (кроме зданий, сооружений) | DM36: инвентарный | EP36: =+Itemdata_1.1!B35 -> 000000000001236
DM37: заводской | EP37: =+Itemdata_1.1!B36
DM38: сетевой | EP38: =+Itemdata_1.1!B49 -> N3501400000000620000
DN39: Государственная | EF39: номер
A40: Объект основных средств | Z40: =+Itemdata_1.1!B39 -> "Системный блок HP dc7600 SFF P4-630" | DN40: регистрация прав на недвижимость | EF40: дата
...

Sheet Itemdata_1.1
A2: Руководитель организации-получателя (должность) | B2: Начальник
A3: Расшифровка подписи
A4: Дата_День | B4: =NOW() -> 41568.63
A5: Дата_Месяц
A6: Дата_Год | B6: =YEAR(B4) -> 2013
A7: Руководитель организации-сдатчика
A8: Расшифровка подписи
A9: Дата
A10: Дата_Месяц
A11: Дата_Год
A12: Организация-сдатчик (Наименование )
A13: Код по ОКУД
A14: Код по ОКПО
A15: Адрес
A16: Телефон
A17: Факс
A18: Банковские реквизиты
A19: Наименование структурного подразделения
A20: Организация-получатель (Наименование ) | B20: ОАО «ТрансКонтейнер» | C20: N350
A21: Код по ОКПО | B21: 94421386
A22: Адрес | B22: 107174 Москва Каланчевская 6/2
A23: Телефон
A24: Факс
A25: Банковские реквизиты
A26: Наименование структурного подразделения
A27: Основание для составления акта
A28: Номер
A29: Дата
A30: Дата принятия к бухгалтерскому учету | B30: 02.10.2006
A31: Дата списания с бухгалтерского учета
A32: Счет, субсчет, код аналитического учета | B32: 01 04 100100
A33: по ОКОФ | B33: 14 3020201
A34: Номер амортизационной группы | B34: 03
A35: Инвентарный номер | B35: 000000000001236
A36: Заводской номер
A37: Номер Гос. рег. прав на недвижимость
A38: Дата регистрации прав на недвижимость
A39: Объект ОС | B39: "Системный блок HP dc7600 SFF P4-630"
A40: Место нахождения ОС | B40: техническое МВЗ
A41: Организация- изготовитель
...

Sheet Itemdata_1.2
A1: Наим. констр.эл | B1: Основной объект | C1: Присп.Принадл. и т.д. | D1: Присп.Принадл. и т.д. | E1: Присп.Принадл. и т.д. | F1: Присп.Принадл. и т.д. | G1: Примечание

Sheet Itemdata_2.1
K1: Сведения о состоянии объекта ОС на дату передачи
A2: Дата выпуска | B2: Дата ввода в эксплуатацию | C2: Дата последнего кап. ремонта | D2: Фактический срок эксплуатации 1 | E2: Фактический срок эксплуатации 2 | F2: Фактический срок эксплуатации 3 | G2: Фактический срок эксплуатации 4 | H2: Срок полезного использования 1 | I2: Срок полезного использования 2 | J2: Срок полезного использования 3 | K2: Срок полезного использования 4 | L2: Сумма начисленной амортизации (износа), | M2: Остаточная стоимость, | N2: Стоимость приобретения (договорная стоимость) | O2: Первоначальная стоимость на дату принятия к бухгалтерскому учету | P2: Срок полезного использования | Q2: Наименование способа нач. ам-ции | R2: Норма
A3: 2006 | B3: 02.10.2006 | C3: - | F3: 001 | G3: м. | H3: 3 | I3: лет. | J3: 1 | K3: мес. | L3: 0 | M3: 0 | N3: 23858 | O3: - | Q3: линейный | R3: 2.703
A4: - | B4: - | C4: - | F4: 001 | G4: м. | H4: 3 | I4: лет. | J4: 1 | K4: мес. | L4: 0 | M4: 0 | N4: 0 | O4: - | P4: - | Q4: линейный | R4: 2.703
A5: - | B5: - | C5: - | L5: - | M5: - | N5: - | O5: - | P5: - | Q5: - | R5: -
A6: - | B6: - | C6: - | L6: - | M6: - | N6: - | O6: - | P6: - | Q6: - | R6: -
A7: - | B7: - | C7: - | L7: - | M7: - | N7: - | O7: - | P7: - | Q7: - | R7: -
A8: - | B8: - | C8: - | L8: - | M8: - | N8: - | O8: - | P8: - | Q8: - | R8: -
A9: - | B9: - | C9: - | L9: - | M9: - | N9: - | O9: - | P9: - | Q9: - | R9: -
A10: - | B10: - | C10: - | L10: - | M10: - | N10: - | O10: - | P10: - | Q10: - | R10: -
A11: - | B11: - | C11: - | L11: - | M11: - | N11: - | O11: - | P11: - | Q11: - | R11: -
A12: - | B12: - | C12: - | L12: - | M12: - | N12: - | O12: - | P12: - | Q12: - | R12: -
A13: - | B13: - | C13: - | L13: - | M13: - | N13: - | O13: - | P13: - | Q13: - | R13: -
A14: - | B14: - | C14: - | L14: - | M14: - | N14: - | O14: - | P14: - | Q14: - | R14: -
A15: - | B15: - | C15: - | L15: - | M15: - | N15: - | O15: - | P15: - | Q15: - | R15: -
A16: - | B16: - | C16: - | L16: - | M16: - | N16: - | O16: - | P16: - | Q16: - | R16: -
... A60: - | B60: - | C60: - | L60: - | M60: - | N60: - | O60: - | P60: - | Q60: - | R60: -

Sheet Itemdata_2.2
A1: Краткая индивидуальная характеристика объекта ОС
A2: Наименование ОС | B2: Количество | C2: Наименование драг. металлов | D2: Номенклатурный номер | E2: Единица измерения | F2: Количество | G2: Масса | H2: Другие характеристики
A3: - | B3: - | C3: - | D3: - | E3: - | F3: - | G3: - | H3: -
A4: - | B4: - | C4: - | D4: - | E4: - | F4: - | G4: - | H4: -
A5: - | B5: - | C5: - | D5: - | E5: - | F5: - | G5: - | H5: -
A6: - | B6: - | C6: - | D6: - | E6: - | F6: - | G6: - | H6: -
A7: - | B7: - | C7: - | D7: - | E7: - | F7: - | G7: - | H7: -
A8: - | B8: - | C8: - | D8: - | E8: - | F8: - | G8: - | H8: -
A9: - | B9: - | C9: - | D9: - | E9: - | F9: - | G9: - | H9: -
A10: - | B10: - | C10: - | D10: - | E10: - | F10: - | G10: - | H10: -
A11: - | B11: - | C11: - | D11: - | E11: - | F11: - | G11: - | H11: -
A12: - | B12: - | C12: - | D12: - | E12: - | F12: - | G12: - | H12: -
A13: - | B13: - | C13: - | D13: - | E13: - | F13: - | G13: - | H13: -
... A60: - | B60: - | C60: - | D60: - | E60: - | F60: - | G60: - | H60: -

Sheet Itemdata_2.3
A1: Данные от сдатчика!
A2: НачалСтроит-ва | B2: ОкончСтроит-ва | C2: ПоследРекМодерн | D2: ГодВыпуска | E2: ДатаВводаВЭкспл | F2: ПоследКапРем | G2: СуммаНачислАморт | H2: ОстСтоим | I2: ФактСрок (год) | J2: ФакСрок (мес) | K2: СПИ (год) | L2: СПИ (мес) | M2: Приложение | N2: Дата Испыт | O2: Соответствует | P2: Не соответствует | Q2: Требуется | R2: Не требуется | S2: Текст "Не соответствует" | T2: Текст "Не соответствует" | U2: Текст "Требуется" | V2: Текст "Требуется" | W2: Заключение комиссии_1 | X2: Заключение комиссии_2 | Y2: Заключение комиссии_3 | Z2: Заключение комиссии_4 | AA2: Заключение комиссии_5 | AB2: Заключение комиссии_6
A3: - | B3: - | C3: - | D3: - | E3: 02.10.2006 | F3: - | G3: - | H3: - | I3: 0 | J3: 0 | K3: 0 | L3: 0 | M3: -
H4: - | I4: 0 | J4: 0 | K4: 0 | L4: 0
G5: - | H5: - | I5: 0 | J5: 0 | K5: 0 | L5: 0
H6: - | I6: 0 | J6: 0 | K6: 0 | L6: 0
I7: 0 | K7: 0 | L7: 0
I8: 0 | K8: 0
I9: 0
I10: 0
I11: 0
I12: 0
I13: 0
I14: 0
I15: 0
I16: 0
I17: 0
I18: 0
I19: 0
I20: 0
... I60: 0

Sheet Itemdata_3.1
A2: Дата результата испытания_День
A3: Дата результата испытания_Месяц
A4: Дата результата испытания_Год
A5: Что не соответствует
A6: Что требуется
A7: Заключение комиссии
A8: Техническая документация
A9: Председатель комиссии
A10: Расшифровка подписи
A11: Члены комиссии
A12: Расшифровка подписи
A13: Члены комиссии
... A15: Сдал_ Должность
A16: Расшифровка подписи | B16: ТЕХНИЧЕСКИЙ
A17: Табельный номер | B17: 03500000
A18: Дата_День
A19: Дата_Месяц
A20: Дата_Год
A21: Гл.бух_Расшифровка подписи
A22: Принял_Должность
A23: Расшифровка подписи
A24: Дата_День
A25: Дата_Месяц
A26: Дата_Год
A27: Доверенность_Дата_День
A28: Доверенность_Дата_Месяц
A29: Доверенность_Дата_Год
... A37: Табельный номер
A38: Номер документа | B38: 140000000062/0000
A39: Дата составления
A40: Гл.бух_Расшифровка подписи
A41: Члены комиссии_3
A42: Расшифровка подписи_3
A43: Члены комиссии_4
A44: Расшифровка подписи_4
A45: Члены комиссии_5
A46: Расшифровка подписи_5
A47: Члены комиссии_6
A48: Расшифровка подписи_6

Sheet Соответствие
A1: LIST1 | B1: Itemdata_1.1 | C1: LIST1 | D1: Itemdata_2.1 | E1: LIST1 | F1: Itemdata_2.2 | G1: LIST1 | H1: Itemdata_3.1
A2: A6 | B2: B2 | C2: A60 | D2: A3 | E2: A67 | F2: A3 | G2: AF83 | H2: B2
A3: AS6 | B3: B3 | C3: K60 | D3: B3 | E3: BG67 | F3: B3 | G3: AL83 | H3: B3
A4: I8, P8, AM8 | B4: B4,B5,B6 | C4: W60 | D4: C3 | E4: BT67 | F4: C3 | G4: BK83 | H4: B4
A5: CS6 | B5: B7 | C5: AK60 | D5: D3 | E5: CX67 | F5: D3 | G5: A86 | H5: B5
A6: EK6 | B6: B8 | D6: E3 | E6: DS67 | F6: E3 | G6: CD86 | H6: B6
A7: DA8, DH8, EE8 | B7: B9,B10,B11 | D7: F3 | E7: EG67 | F7: F3 | G7: W90 | H7: B7
A8: Y12 | B8: B12 | D8: G3 | E8: ET67 | F8: G3 | G8: AN92 | H8: B8
A9: EP11 | B9: B13 | C9: AY60 | D9: H3 | G9: AC93 | H9: B9
A10: EP12 | B10: B14 | D10: I3 | G10: CD93 | H10: B10
A11: A14 | B11: B15 | D11: J3 | G11: AC95 | H11: B11
A12: A14 | B12: B16 | D12: K3 | G12: CD95 | H12: B12
A13: A14 | B13: B17 | C13: BO60 | D13: L3 | G13: AC97 | H13: B13
A14: A16 | B14: B18 | C14: CC60 | D14: M3 | G14: CD97 | H14: B14
A15: A18 | B15: B19 | C15: CP60 | D15: N3 | G15: K103 | H15: B15
A16: V20 | B16: B20 | C16: DD60 | D16: O3 | G16: BD103 | H16: B16
A17: EP19 | B17: B21 | C17: DT60 | D17: P3 | G17: BM106 | H17: B17
A18: A22 | B18: B22 | C18: EI60 | D18: Q3 | G18: C106 | H18: B18
A19: A22 | B19: B23 | C19: EX60 | D19: R3 | G19: J106 | H19: B19
A20: A22 | B20: B24 | G20: AK106 | H20: B20
A21: A24 | B21: B25 | G21: AS121 | H21: B21
A22: A26 | B22: B26 | G22: CO103 | H22: B22
A23: AF28 | B23: B27 | G23: EH103 | H23: B23
A24: EP27 | B24: B28 | G24: CF106 | H24: B24
A25: EP29 | B25: B29 | G25: CM106 | H25: B25
A26: EP31 | B26: B30 | G26: DN106 | H26: B26
A27: EP32 | B27: B31 | G27: CX108 | H27: B27
A28: EP33 | B28: B32 | G28: DE108 | H28: B28
A29: EP34 | B29: B33 | G29: EF108 | H29: B29
A30: EP35 | B30: B34 | G30: EQ108 | H30: B30
A31: EP36 | B31: B35 | G31: CO110 | H31: B31
... A40: A42 | B40: B44 | G40: DV121 | H40: B40
